Workbook

Sheet 全国暖通、空调室外气象参数表《GB50736-2012》 
A1: 全国民用建筑供暖通风与空气调节设计规范《GB50736-2012》 附录A 室外气象参数 2012-12-08日编制於北京
A2: 省份 | B2: 城市名称 | D2: 站台名称 | E2: 台站位置 | H2: 统计年份 | I2: 年平均温度（℃) | J2: 室外计算温、湿度(℃) | S2: 室外风向、风速及频率 注明：E-东；东风。S-南；南风。W-西；西风。N-北；北风。C-静风。 | AC2: 冬季日照百分率(%) | AD2: 最大冻土深度（㎝) | AE2: 大气压力（hPa) | AG2: 设计计算用供暖期天数及其平均温度 | AM2: 极端最高温度（℃) | AN2: 极端最低温度（℃)
E3: 北纬 | F3: 东经 | G3: 海拔（m) | J3: 冬季 | N3: 夏季 | S3: 夏季 | W3: 冬季 | AA3: 年最多风向 | AB3: 年最多风向的频率(%) | AE3: 冬季 | AF3: 夏季 | AG3: 日平均温度≤+5℃的天数 | AH3: 日平均温度≤+5℃的起止日期 | AI3: 平均温度≤+5℃期间内的平均温度（℃) | AJ3: 日平均温度≤+8℃的天数 | AK3: 日平均温度≤+8℃的起止日期 | AL3: 平均温度≤+8℃期间内的平均温度（℃)
J4: 供暖(℃) | K4: 通风(℃) | L4: 空调(℃) | M4: 空调相对湿度(%) | N4: 空气调节干球温度(℃) | O4: 空气调节室外计算湿球温度(℃） | P4: 通风计算温度(℃） | Q4: 通风计算相对湿度(%) | R4: 空气调节室外计算日平均温度(℃ | S4: 平均风速（m/s） | T4: 最多风向 | U4: 最多风向的频率(%) | V4: 最多风向的平均风速（m/s） | W4: 平均风速（m/s） | X4: 最多风向 | Y4: 最多风向的频率(%) | Z4: 最多风向的平均风速（m/s）
A5: 北京 | B5: 1 | C5: 北京 | D5: 北京5411 | E5: 39°48′ | F5: 116°28′ | G5: 31.3 | H5: 1971-2000 | I5: 12.3 | J5: -7.6 | K5: -3.6 | L5: -9.9 | M5: 44 | N5: 33.5 | O5: 26.4 | P5: 29.7 | Q5: 61 | R5: 29.6 | S5: 2.1 | T5: C SW | U5: 18 10 | V5: 3 | W5: 2.6 | X5: C N | Y5: 19 12 | Z5: 4.7 | AA5: C SW | AB5: 17 10 | AC5: 64 | AD5: 66 | AE5: 1021.7 | AF5: 1000.2 | AG5: 123 | AH5: 11.12--03.14 | AI5: -0.7 | AJ5: 144 | AK5: 11.04--03.27 | AL5: 0.3 | AM5: 41.9 | AN5: -18.3
A6: 天津 | B6: 1 | C6: 天津 | D6: 天津54527 | E6: 39°05′ | F6: 117°04′ | G6: 2.5 | H6: 1971-2000 | I6: 12.7 | J6: -7 | K6: -3.5 | L6: -9.6 | M6: 56 | N6: 33.9 | O6: 26.8 | P6: 29.8 | Q6: 63 | R6: 29.4 | S6: 2.2 | T6: C S | U6: 15 9 | V6: 2.4 | W6: 2.4 | X6: C N | Y6: 20 11 | Z6: 4.8 | AA6: C SW | AB6: 16 9 | AC6: 58 | AD6: 58 | AE6: 1027.1 | AF6: 1005.2 | AG6: 121 | AH6: 11.13--03.13 | AI6: -0.6 | AJ6: 142 | AK6: 11.06--03.27 | AL6: 0.4 | AM6: 40.5 | AN6: -17.8
B7: 2 | C7: 塘沽 | D7: 塘沽54623 | E7: 39°00′ | F7: 117°43′ | G7: 2.7 | H7: 1971-2000 | I7: 12.6 | J7: -6.8 | K7: -3.3 | L7: -9.2 | M7: 59 | N7: 32.5 | O7: 26.9 | P7: 28.8 | Q7: 68 | R7: 29.6 | S7: 4.2 | T7: SSE | U7: 12 | V7: 4.3 | W7: 3.9 | X7: NNW | Y7: 13 | Z7: 5.8 | AA7: NNW | AB7: 8 | AC7: 63 | AD7: 59 | AE7: 1026.3 | AF7: 1004.6 | AG7: 122 | AH7: 11.15--03.16 | AI7: -0.4 | AJ7: 143 | AK7: 11.07--03.29 | AL7: 0.6 | AM7: 40.9 | AN7: -15.4
A8: 河北省 | B8: 1 | C8: 石家庄 | D8: 石家庄53698 | E8: 38°02′ | F8: 114°25′ | G8: 81 | H8: 1971-2000 | I8: 13.4 | J8: -6.2 | K8: -2.3 | L8: -8.8 | M8: 55 | N8: 35.1 | O8: 26.8 | P8: 30.8 | Q8: 60 | R8: 30 | S8: 1.7 | T8: C S | U8: 26 13 | V8: 2.6 | W8: 1.8 | X8: C NNE | Y8: 25 12 | Z8: 2 | AA8: C S | AB8: 25 12 | AC8: 56 | AD8: 56 | AE8: 1017.2 | AF8: 995.8 | AG8: 111 | AH8: 11.15--03.05 | AI8: 0.1 | AJ8: 140 | AK8: 11.07--03.26 | AL8: 1.5 | AM8: 41.5 | AN8: -19.3
B9: 2 | C9: 唐山 | D9: 唐山54534 | E9: 39°40′ | F9: 118°09′ | G9: 27.8 | H9: 1971-2000 | I9: 11.5 | J9: -9.2 | K9: -5.1 | L9: -11.6 | M9: 55 | N9: 32.9 | O9: 26.3 | P9: 29.2 | Q9: 63 | R9: 28.5 | S9: 2.3 | T9: C ESE | U9: 14 11 | V9: 2.8 | W9: 2.2 | X9: C WNW | Y9: 22 11 | Z9: 2.9 | AA9: C ESE | AB9: 17 18 | AC9: 60 | AD9: 72 | AE9: 1023.6 | AF9: 1002.4 | AG9: 130 | AH9: 11.10--03.19 | AI9: -1.6 | AJ9: 146 | AK9: 11.04--03.29 | AL9: -0.7 | AM9: 39.6 | AN9: -22.7
B10: 3 | C10: 邢台 | D10: 邢台53798 | E10: 37°04′ | F10: 114°30′ | G10: 76.8 | H10: 1971-2000 | I10: 13.9 | J10: -5.5 | K10: -1.6 | L10: -8 | M10: 57 | N10: 35.1 | O10: 26.9 | P10: 31 | Q10: 61 | R10: 30.2 | S10: 1.7 | T10: C SSW | U10: 23 13 | V10: 2.3 | W10: 1.4 | X10: C NNE | Y10: 27 10 | Z10: 2 | AA10: C SSW | AB10: 24 13 | AC10: 56 | AD10: 46 | AE10: 1017.7 | AF10: 996.2 | AG10: 105 | AH10: 11.19--03.03 | AI10: 0.5 | AJ10: 129 | AK10: 11.08--03.16 | AL10: 1.8 | AM10: 41.1 | AN10: -20.2
B11: 4 | C11: 保定 | D11: 保定54602 | E11: 38°51′ | F11: 115°31′ | G11: 17.2 | H11: 1971-2000 | I11: 12.9 | J11: -7 | K11: -3.2 | L11: -9.5 | M11: 55 | N11: 34.8 | O11: 26.6 | P11: 30.4 | Q11: 61 | R11: 29.8 | S11: 2 | T11: C SW | U11: 18 14 | V11: 2.5 | W11: 1.8 | X11: C SW | Y11: 23 12 | Z11: 2.3 | AA11: C SW | AB11: 19 14 | AC11: 56 | AD11: 58 | AE11: 1025.1 | AF11: 1002.9 | AG11: 119 | AH11: 11.13--03.11 | AI11: -0.5 | AJ11: 142 | AK11: 11.05--03.27 | AL11: 0.7 | AM11: 41.6 | AN11: -19.6
B12: 5 | C12: 张家口 | D12: 张家口54401 | E12: 40°47′ | F12: 114°53′ | G12: 724.2 | H12: 1971-2000 | I12: 8.8 | J12: -13.6 | K12: -8.3 | L12: -16.2 | M12: 41 | N12: 32.1 | O12: 22.6 | P12: 27.8 | Q12: 50 | R12: 27 | S12: 2.1 | T12: C SE | U12: 19 15 | V12: 2.9 | W12: 2.8 | X12: N | Y12: 35 | Z12: 3.5 | AA12: N | AB12: 26 | AC12: 65 | AD12: 136 | AE12: 939.5 | AF12: 925 | AG12: 146 | AH12: 11.03--03.28 | AI12: -3.9 | AJ12: 168 | AK12: 10.20--04.05 | AL12: -2.6 | AM12: 39.2 | AN12: -24.6
B13: 6 | C13: 承德 | D13: 承德54423 | E13: 40°58′ | F13: 117°56′ | G13: 377.2 | H13: 1971-2000 | I13: 9.1 | J13: -13.3 | K13: -9.1 | L13: -15.7 | M13: 51 | N13: 32.7 | O13: 24.1 | P13: 28.7 | Q13: 55 | R13: 27.4 | S13: 0.9 | T13: C SSW | U13: 61 6 | V13: 2.5 | W13: 1 | X13: C NW | Y13: 66 10 | Z13: 3.3 | AA13: C NW | AB13: 61 6 | AC13: 65 | AD13: 126 | AE13: 980.5 | AF13: 963.3 | AG13: 145 | AH13: 11.03--03.27 | AI13: -4.1 | AJ13: 166 | AK13: 10.21--04.04 | AL13: -2.9 | AM13: 43.3 | AN13: -24.2
B14: 7 | C14: 秦皇岛 | D14: 秦皇岛54449 | E14: 39°56′ | F14: 119°36′ | G14: 2.6 | H14: 1971-2000 | I14: 11 | J14: -9.6 | K14: -4.8 | L14: -12 | M14: 51 | N14: 30.6 | O14: 25.9 | P14: 27.5 | Q14: 55 | R14: 27.7 | S14: 2.3 | T14: C WSW | U14: 19 10 | V14: 2.7 | W14: 2.5 | X14: C WNW | Y14: 19 13 | Z14: 3 | AA14: C WNW | AB14: 18 10 | AC14: 64 | AD14: 85 | AE14: 1026.4 | AF14: 1005.6 | AG14: 135 | AH14: 11.12--03.26 | AI14: -1.2 | AJ14: 153 | AK14: 11.04--04.05 | AL14: -0.3 | AM14: 39.2 | AN14: -20.8
B15: 8 | C15: 沧州 | D15: 沧州54616 | E15: 38°20′ | F15: 116°50′ | G15: 9.6 | H15: 1971-1995 | I15: 12.9 | J15: -7.1 | K15: -3 | L15: -9.6 | M15: 57 | N15: 34.3 | O15: 26.7 | P15: 30.1 | Q15: 63 | R15: 29.7 | S15: 2.9 | T15: SW | U15: 12 | V15: 2.7 | W15: 2.6 | X15: SW | Y15: 12 | Z15: 2.8 | AA15: SW | AB15: 14 | AC15: 64 | AD15: 43 | AE15: 1027 | AF15: 1004 | AG15: 118 | AH15: 11.15--03.12 | AI15: -0.5 | AJ15: 141 | AK15: 11.07--03.27 | AL15: 0.7 | AM15: 40.5 | AN15: -19.5
B16: 9 | C16: 廊坊 | D16: 霸州54518 | E16: 39°07′ | F16: 116°23′ | G16: 9 | H16: 1971-2000 | I16: 12.2 | J16: -8.3 | K16: -4.4 | L16: -11 | M16: 54 | N16: 34.4 | O16: 26.6 | P16: 30.1 | Q16: 61 | R16: 29.6 | S16: 2.2 | T16: C SW | U16: 12 9 | V16: 2.5 | W16: 2.1 | X16: C NE | Y16: 19 11 | Z16: 3.3 | AA16: C SW | AB16: 14 10 | AC16: 57 | AD16: 67 | AE16: 1026.4 | AF16: 1004 | AG16: 124 | AH16: 11.11--03.14 | AI16: -1.3 | AJ16: 143 | AK16: 11.05--03.27 | AL16: -0.3 | AM16: 41.3 | AN16: -21.5
B17: 10 | C17: 衡水 | D17: 饶阳54606 | E17: 38°14′ | F17: 115°44′ | G17: 18.9 | H17: 1971-2000 | I17: 12.5 | J17: -7.9 | K17: -3.9 | L17: -10.4 | M17: 59 | N17: 34.8 | O17: 26.9 | P17: 30.5 | Q17: 61 | R17: 29.6 | S17: 2.2 | T17: C SW | U17: 15 11 | V17: 3 | W17: 2 | X17: C SW | Y17: 19 9 | Z17: 2.6 | AA17: C SW | AB17: 15 11 | AC17: 63 | AD17: 77 | AE17: 1024.9 | AF17: 1002.8 | AG17: 122 | AH17: 11.12--03.13 | AI17: -0.9 | AJ17: 143 | AK17: 11.05--03.27 | AL17: 0.2 | AM17: 41.2 | AN17: -22.6
A18: 山西省 | B18: 1 | C18: 太原 | D18: 太原53772 | E18: 37°47′ | F18: 112°33′ | G18: 778.3 | H18: 1971-2000 | I18: 10 | J18: -10.1 | K18: -5.5 | L18: -12.8 | M18: 50 | N18: 31.5 | O18: 23.8 | P18: 27.8 | Q18: 58 | R18: 26.1 | S18: 1.8 | T18: C N | U18: 30 10 | V18: 2.4 | W18: 2 | X18: C N | Y18: 30 13 | Z18: 2.6 | AA18: C N | AB18: 29 11 | AC18: 57 | AD18: 72 | AE18: 933.5 | AF18: 919.8 | AG18: 141 | AH18: 10.06--03.26 | AI18: -1.7 | AJ18: 160 | AK18: 10.23--03.31 | AL18: -0.7 | AM18: 37.4 | AN18: -22.7
B19: 2 | C19: 大同 | D19: 大同53487 | E19: 40°06′ | F19: 113°20′ | G19: 1067.2 | H19: 1971-2000 | I19: 7 | J19: -16.3 | K19: -10.6 | L19: -18.9 | M19: 50 | N19: 30.9 | O19: 21.2 | P19: 26.4 | Q19: 49 | R19: 25.3 | S19: 2.5 | T19: C NNE | U19: 17 12 | V19: 3.1 | W19: 2.8 | X19: N | Y19: 19 | Z19: 3.3 | AA19: C NNE | AB19: 16 15 | AC19: 61 | AD19: 186 | AE19: 899.9 | AF19: 889.1 | AG19: 163 | AH19: 10.24--04.04 | AI19: -4.8 | AJ19: 183 | AK19: 10.14--04.14 | AL19: -3.5 | AM19: 37.2 | AN19: -27.2
B20: 3 | C20: 阳泉 | D20: 阳泉53782 | E20: 37°51′ | F20: 113°33′ | G20: 741.9 | H20: 1971-2000 | I20: 11.3 | J20: -8.3 | K20: -3.4 | L20: -10.4 | M20: 43 | N20: 32.8 | O20: 23.6 | P20: 28.2 | Q20: 55 | R20: 27.4 | S20: 1.6 | T20: C ENE | U20: 33 9 | V20: 2.3 | W20: 2.2 | X20: C NNW | Y20: 30 19 | Z20: 3.7 | AA20: C NNW | AB20: 31 13 | AC20: 62 | AD20: 62 | AE20: 937.1 | AF20: 923.8 | AG20: 126 | AH20: 11.12--03.17 | AI20: -0.5 | AJ20: 146 | AK20: 11.04--03.29 | AL20: 0.3 | AM20: 40.2 | AN20: -16.2
B21: 4 | C21: 运城 | D21: 运城53959 | E21: 35°02′ | F21: 111°01′ | G21: 376 | H21: 1971-2000 | I21: 9.14 | J21: -4.5 | K21: -0.9 | L21: -7.4 | M21: 57 | N21: 35.8 | O21: 26 | P21: 31.3 | Q21: 55 | R21: 31.5 | S21: 3.1 | T21: SSE | U21: 16 | V21: 5 | W21: 2.4 | X21: C W | Y21: 24 9 | Z21: 2.8 | AA21: C SSE | AB21: 18 11 | AC21: 49 | AD21: 39 | AE21: 982 | AF21: 962.7 | AG21: 101 | AH21: 11.22--03.02 | AI21: 0.9 | AJ21: 127 | AK21: 11.08--03.14 | AL21: 2 | AM21: 41.2 | AN21: -18.9
B22: 5 | C22: 晋城 | D22: 阳城53975 | E22: 35°29′ | F22: 112°24′ | G22: 659.5 | H22: 1971-2000 | I22: 11.8 | J22: -6.6 | K22: -2.6 | L22: -9.1 | M22: 53 | N22: 32.7 | O22: 24.6 | P22: 28.8 | Q22: 59 | R22: 27.3 | S22: 1.7 | T22: C SSE | U22: 35 11 | V22: 2.9 | W22: 1.9 | X22: C NW | Y22: 42 12 | Z22: 4.9 | AA22: C NW | AB22: 37 9 | AC22: 58 | AD22: 39 | AE22: 947.4 | AF22: 932.4 | AG22: 120 | AH22: 11.14--03.13 | AI22: 0 | AJ22: 143 | AK22: 11.06--03.28 | AL22: 1 | AM22: 38.5 | AN22: -17.2
B23: 6 | C23: 朔州 | D23: 右玉53478 | E23: 40°00′ | F23: 112°27′ | G23: 1348.8 | H23: 1971-2000 | I23: 3.9 | J23: -20.8 | K23: -14.4 | L23: -25.4 | M23: 61 | N23: 29 | O23: 19.8 | P23: 24.5 | Q23: 50 | R23: 22.5 | S23: 2.1 | T23: C ESE | U23: 30 11 | V23: 2.8 | W23: 2.3 | X23: C NW | Y23: 41 11 | Z23: 5 | AA23: C WNW | AB23: 32 8 | AC23: 71 | AD23: 169 | AE23: 868.6 | AF23: 860.7 | AG23: 182 | AH23: 10.--04.13 | AI23: -6.9 | AJ23: 208 | AK23: 10.01--04.26 | AL23: -5.2 | AM23: 34.4 | AN23: -40.4
B24: 7 | C24: 晋中 | D24: 榆社53787 | E24: 37°04′ | F24: 112°59′ | G24: 1041.4 | H24: 1971-2000 | I24: 8.8 | J24: -11.1 | K24: -6.6 | L24: -13.6 | M24: 49 | N24: 30.8 | O24: 22.3 | P24: 26.8 | Q24: 55 | R24: 24.8 | S24: 1.5 | T24: C SSW | U24: 39 9 | V24: 2.8 | W24: 1.3 | X24: C E | Y24: 42 14 | Z24: 1.9 | AA24: C E | AB24: 38 9 | AC24: 62 | AD24: 76 | AE24: 902.6 | AF24: 892 | AG24: 144 | AH24: 11.05--03.28 | AI24: -2.6 | AJ24: 168 | AK24: 10.20--04.05 | AL24: -1.3 | AM24: 36.7 | AN24: -25.1
B25: 8 | C25: 忻州 | D25: 原平53673 | E25: 38°44′ | F25: 112°43′ | G25: 828.2 | H25: 1971-2000 | I25: 9 | J25: -12.3 | K25: -7.7 | L25: -14.7 | M25: 47 | N25: 31.8 | O25: 22.9 | P25: 27.6 | Q25: 53 | R25: 26.2 | S25: 1.9 | T25: C NNE | U25: 20 11 | V25: 2.4 | W25: 2.3 | X25: C NNE | Y25: 26 14 | Z25: 3.8 | AA25: C NNE | AB25: 22 12 | AC25: 60 | AD25: 121 | AE25: 926.9 | AF25: 913.8 | AG25: 145 | AH25: 11.03--03.27 | AI25: -3.2 | AJ25: 168 | AK25: 10.20--04.05 | AL25: -1.9 | AM25: 38.1 | AN25: -25.8
B26: 9 | C26: 临汾 | D26: 临汾53868 | E26: 36°04′ | F26: 111°30′ | G26: 449.5 | H26: 1971-2000 | I26: 12.6 | J26: -6.6 | K26: -2.7 | L26: -10 | M26: 58 | N26: 34.6 | O26: 25.7 | P26: 30.6 | Q26: 56 | R26: 29.3 | S26: 1.8 | T26: C SW | U26: 24 9 | V26: 3 | W26: 1.6 | X26: C SW | Y26: 35 7 | Z26: 2.6 | AA26: C SW | AB26: 31 9 | AC26: 47 | AD26: 57 | AE26: 972.5 | AF26: 954.2 | AG26: 114 | AH26: 11.13--03.06 | AI26: -0.2 | AJ26: 142 | AK26: 11.06--03.27 | AL26: 1.1 | AM26: 40.5 | AN26: -23.1
B27: 10 | C27: 吕梁 | D27: 离石53764 | E27: 37°30′ | F27: 111°06′ | G27: 950.8 | H27: 1971-2000 | I27: 9.1 | J27: -12.6 | K27: -7.6 | L27: -16 | M27: 55 | N27: 32.4 | O27: 22.9 | P27: 28.1 | Q27: 52 | R27: 26.3 | S27: 2.6 | T27: C NE | U27: 22 17 | V27: 2.5 | W27: 2.1 | X27: NE | Y27: 26 | Z27: 2.5 | AA27: NE | AB27: 20 | AC27: 58 | AD27: 104 | AE27: 914.5 | AF27: 901.3 | AG27: 143 | AH27: 11.05--03.27 | AI27: -3 | AJ27: 166 | AK27: 10.20--04.03 | AL27: -1.7 | AM27: 38.4 | AN27: -26
A28: 内蒙古 | B28: 1 | C28: 呼和浩特 | D28: 呼和浩特53463 | E28: 40°49′ | F28: 111°41′ | G28: 1063 | H28: 1971-2000 | I28: 6.7 | J28: -17 | K28: -11.6 | L28: -20.3 | M28: 58 | N28: 30.6 | O28: 21 | P28: 26.5 | Q28: 48 | R28: 25.9 | S28: 1.8 | T28: C SW | U28: 36 8 | V28: 3.4 | W28: 1.5 | X28: C NNW | Y28: 50 9 | Z28: 4.2 | AA28: C NNW | AB28: 40 7 | AC28: 63 | AD28: 156 | AE28: 901.2 | AF28: 889.6 | AG28: 167 | AH28: 10.20--04.04 | AI28: -5.3 | AJ28: 184 | AK28: 10.12--04.13 | AL28: -4.1 | AM28: 38.5 | AN28: -30.5
B29: 2 | C29: 包头 | D29: 包头53446 | E29: 40°40′ | F29: 109°51′ | G29: 1067.2 | H29: 1971-2000 | I29: 7.2 | J29: -16.6 | K29: -11.1 | L29: -19.7 | M29: 55 | N29: 31.7 | O29: 20.9 | P29: 27.4 | Q29: 43 | R29: 26.5 | S29: 2.6 | T29: C SE | U29: 14 11 | V29: 2.9 | W29: 2.4 | X29: N | Y29: 21 | Z29: 3.4 | AA29: N | AB29: 16 | AC29: 68 | AD29: 157 | AE29: 901.2 | AF29: 889.1 | AG29: 164 | AH29: 10.21--04.02 | AI29: -5.1 | AJ29: 182 | AK29: 10.13--04.12 | AL29: -3.9 | AM29: 39.2 | AN29: -31.4
B30: 3 | C30: 赤峰 | D30: 赤峰54218 | E30: 42°16′ | F30: 118°56′ | G30: 568 | H30: 1971-2000 | I30: 7.5 | J30: -16.2 | K30: -10.7 | L30: -18.8 | M30: 43 | N30: 32.7 | O30: 22.6 | P30: 28 | Q30: 50 | R30: 27.4 | S30: 2.2 | T30: C WSW | U30: 20 13 | V30: 2.5 | W30: 2.3 | X30: C W | Y30: 26 14 | Z30: 3.1 | AA30: C W | AB30: 21 13 | AC30: 70 | AD30: 201 | AE30: 955.1 | AF30: 941.1 | AG30: 161 | AH30: 10.26--04.04 | AI30: -5 | AJ30: 179 | AK30: 10.16--04.12 | AL30: -3.8 | AM30: 40.4 | AN30: -28.8
B31: 4 | C31: 通辽 | D31: 通辽54135 | E31: 43°36′ | F31: 122°16′ | G31: 178.5 | H31: 1971-2000 | I31: 6.6 | J31: -19 | K31: -13.5 | L31: -21.8 | M31: 54 | N31: 32.3 | O31: 24.5 | P31: 28.2 | Q31: 57 | R31: 27.3 | S31: 3.5 | T31: SSW | U31: 17 | V31: 4.6 | W31: 3.7 | X31: NW | Y31: 16 | Z31: 4.4 | AA31: SSW | AB31: 11 | AC31: 76 | AD31: 179 | AE31: 1002.6 | AF31: 984.4 | AG31: 166 | AH31: 10.21--04.04 | AI31: -6.7 | AJ31: 184 | AK31: 10.13--04.14 | AL31: -5.4 | AM31: 38.9 | AN31: -31.6
B32: 5 | C32: 鄂尔多斯 | D32: 东胜53543 | E32: 39°50′ | F32: 109°59′ | G32: 1460.4 | H32: 1971-2000 | I32: 6.2 | J32: -16.8 | K32: -10.5 | L32: -19.6 | M32: 52 | N32: 29.1 | O32: 19 | P32: 24.8 | Q32: 43 | R32: 24.6 | S32: 3.1 | T32: SSW | U32: 19 | V32: 3.7 | W32: 2.9 | X32: SSW | Y32: 14 | Z32: 3.1 | AA32: SSW | AB32: 17 | AC32: 73 | AD32: 150 | AE32: 856.7 | AF32: 849.5 | AG32: 168 | AH32: 10.20--04.05 | AI32: -4.9 | AJ32: 189 | AK32: 10.11--04.17 | AL32: -3.6 | AM32: 35.3 | AN32: -28.4
B33: 6 | C33: 呼伦贝尔 | D33: 满州里50514 | E33: 49°34′ | F33: 117°26′ | G33: 661.7 | H33: 1971-2000 | I33: -0.7 | J33: -28.6 | K33: -23.3 | L33: -31.6 | M33: 75 | N33: 29 | O33: 19.9 | P33: 24.1 | Q33: 52 | R33: 23.6 | S33: 3.8 | T33: C E | U33: 13 10 | V33: 4.4 | W33: 3.7 | X33: WSW | Y33: 23 | Z33: 3.9 | AA33: WSW | AB33: 13 | AC33: 70 | AD33: 389 | AE33: 941.9 | AF33: 930.3 | AG33: 210 | AH33: 09.30--04.27 | AI33: -12.4 | AJ33: 229 | AK33: 09.21--05.07 | AL33: -10.8 | AM33: 37.9 | AN33: -40.5
B34: 7 | D34: 海拉尔50527 | E34: 49°13′ | F34: 119°45′ | G34: 610.2 | H34: 1971-2000 | I34: -1 | J34: -31.6 | K34: -25.1 | L34: -34.5 | M34: 79 | N34: 29 | O34: 20.5 | P34: 24.3 | Q34: 54 | R34: 23.5 | S34: 3 | T34: C SSW | U34: 13 8 | V34: 3.1 | W34: 2.3 | X34: C SSW | Y34: 22 19 | Z34: 2.5 | AA34: C SSW | AB34: 15 12 | AC34: 62 | AD34: 242 | AE34: 947.9 | AF34: 935.7 | AG34: 208 | AH34: 10.01--04.26 | AI34: -12.7 | AJ34: 227 | AK34: 09.22--05.06 | AL34: -11 | AM34: 36.6 | AN34: -42.3
B35: 8 | C35: 巴彦淖尔 | D35: 临河53513 | E35: 40°45′ | F35: 107°25′ | G35: 1039.3 | H35: 1971-2000 | I35: 8.1 | J35: -15.3 | K35: -9.9 | L35: -19.1 | M35: 51 | N35: 32.7 | O35: 20.9 | P35: 28.4 | Q35: 39 | R35: 27.5 | S35: 2.1 | T35: C E | U35: 20 10 | V35: 2.5 | W35: 2 | X35: C W | Y35: 30 13 | Z35: 3.4 | AA35: C W | AB35: 24 10 | AC35: 72 | AD35: 138 | AE35: 903.9 | AF35: 891.1 | AG35: 157 | AH35: 10.24--03.29 | AI35: -4.4 | AJ35: 175 | AK35: 10.16--04.08 | AL35: -3.3 | AM35: 39.4 | AN35: -35.3
B36: 9 | C36: 乌兰察布 | D36: 集宁53480 | E36: 41°02′ | F36: 113°04′ | G36: 1419.3 | H36: 1971-2000 | I36: 4.3 | J36: -18.9 | K36: -13 | L36: -21.9 | M36: 55 | N36: 28.2 | O36: 18.9 | P36: 23.8 | Q36: 49 | R36: 22.9 | S36: 2.4 | T36: C WNW | U36: 29 9 | V36: 3.6 | W36: 3 | X36: C WNW | Y36: 33 13 | Z36: 4.9 | AA36: C WNW | AB36: 29 12 | AC36: 72 | AD36: 184 | AE36: 860.2 | AF36: 853.7 | AG36: 181 | AH36: 10.16--04.14 | AI36: -6.4 | AJ36: 206 | AK36: 10.03--04.26 | AL36: -4.7 | AM36: 33.6 | AN36: -32.4
B37: 10 | C37: 兴安盟 | D37: 乌兰浩特50838 | E37: 46°05′ | F37: 122°03′ | G37: 274.7 | H37: 1971-2000 | I37: 5 | J37: -20.5 | K37: -15 | L37: -23.5 | M37: 54 | N37: 31.8 | O37: 23 | P37: 27.1 | Q37: 55 | R37: 26.6 | S37: 2.6 | T37: C NE | U37: 23 7 | V37: 3.9 | W37: 2.6 | X37: C NW | Y37: 27 17 | Z37: 4 | AA37: C NW | AB37: 22 11 | AC37: 69 | AD37: 249 | AE37: 989.1 | AF37: 973.3 | AG37: 176 | AH37: 10.17--04.10 | AI37: -7.8 | AJ37: 193 | AK37: 10.09--04.19 | AL37: -6.5 | AM37: 40.3 | AN37: -33.7
B38: 11 | C38: 锡林郭勒盟 | D38: 二连浩特53068 | E38: 43°39′ | F38: 111°58′ | G38: 964.7 | H38: 1971-2000 | I38: 4 | J38: -24.3 | K38: -18.1 | L38: -27.8 | M38: 69 | N38: 33.2 | O38: 19.3 | P38: 27.9 | Q38: 33 | R38: 27.5 | S38: 4 | T38: NW | U38: 8 | V38: 5.2 | W38: 3.6 | X38: NW | Y38: 16 | Z38: 5.3 | AA38: NW | AB38: 13 | AC38: 76 | AD38: 310 | AE38: 910.5 | AF38: 898.3 | AG38: 181 | AH38: 10.14--04.12 | AI38: -9.3 | AJ38: 196 | AK38: 10.07--04.20 | AL38: -8.1 | AM38: 41.1 | AN38: -37.1
B39: 12 | D39: 锡林浩特54102 | E39: 43°57′ | F39: 116°04′ | G39: 989.5 | H39: 1971-2000 | I39: 2.6 | J39: -25.2 | K39: -18.8 | L39: -27.8 | M39: 72 | N39: 31.1 | O39: 19.9 | P39: 26 | Q39: 44 | R39: 25.4 | S39: 3.3 | T39: C SW | U39: 13 9 | V39: 3.4 | W39: 3.2 | X39: WSW | Y39: 19 | Z39: 4.3 | AA39: C WSW | AB39: 15 13 | AC39: 71 | AD39: 265 | AE39: 906.4 | AF39: 895.9 | AG39: 189 | AH39: 10.11--04.17 | AI39: -9.7 | AJ39: 209 | AK39: 10.01--04.27 | AL39: -8.1 | AM39: 39.2 | AN39: -38
A40: 辽宁省 | B40: 1 | C40: 沈阳 | D40: 沈阳54343 | E40: 41°44′ | F40: 123°27′ | G40: 44.7 | H40: 1971-2000 | I40: 8.4 | J40: -16.9 | K40: -11 | L40: -20.7 | M40: 60 | N40: 31.5 | O40: 25.3 | P40: 28.2 | Q40: 65 | R40: 27.5 | S40: 2.6 | T40: SW | U40: 16 | V40: 3.5 | W40: 2.6 | X40: C NNE | Y40: 13 10 | Z40: 3.6 | AA40: SW | AB40: 13 | AC40: 56 | AD40: 148 | AE40: 1020.8 | AF40: 1000.9 | AG40: 152 | AH40: 10.30--03.30 | AI40: -5.1 | AJ40: 172 | AK40: 10.20--04.09 | AL40: -3.6 | AM40: 36.1 | AN40: -29.4
...

Sheet 1-室外设计气象参数
B1: 使用说明：仅需根据项目情况输入黄色区域的参数
A2: C.0 | B2: 室外设计气象参数《GB50736-2012》 | D2: Design Atmosphere Date of Outdoor | L2: 从气象参数表中复制
G3: 设计地点
A5: 设计地点 | B5: 地理位置 | C5: 省/直辖市/自治区 | D5: Design location | E5: L | F5: — | G5: =L5 -> 0
C6: 序号 | G6: =L6 -> 5 | L6: 5
C7: 市/区/自治州 | D7: Design location | E7: L | F7: — | G7: =L7 -> 常州 | L7: 常州
A8: 气象台站信息 | C8: 台站名称 | D8: Atmosphere station Name | E8: N | F8: — | G8: =L8 -> 常州58343 | L8: 常州58343
C9: 北纬 | D9: Northern latitude | E9: N | F9: ° | G9: =L9 -> 31°46′ | L9: 31°46′
C10: 东经 | D10: East longitude | E10: E | F10: ° | G10: =L10 -> 119°56′ | L10: 119°56′
C11: 海拔 | D11: Height above sea level | E11: H | F11: m | G11: =L11 -> 4.9 | L11: 4.9
C12: 统计年份 | D12: Year of date | E12: Y | F12: — | G12: =L12 -> 1971-2000 | L12: 1971-2000
A13: 室外设计计算 温湿度 | B13: 全年 | C13: 年平均温度 | D13: Average temperatures of year | E13: Ty | F13: ℃ | G13: =L13 -> 15.8 | L13: 15.8
B14: 冬季 | C14: 供暖室外计算温度 | D14: Heating bulb temperature | E14: HB | F14: ℃ | G14: =L14 -> -1.2 | L14: -1.2
B15: 冬季 | C15: 通风室外计算温度 | D15: EFtilated bulb temperature in winter | E15: VB | F15: ℃ | G15: =L15 -> 3.1 | L15: 3.1
B16: 冬季 | C16: 空气调节室外计算温度 | D16: Dry bulb temperature for AC in winter | E16: DB | F16: ℃ | G16: =L16 -> -3.5 | L16: -3.5
B17: 冬季 | C17: 空调调节相对湿度 | D17: Relative humidity in winter | E17: RH | F17: % | G17: =L17 -> 75 | L17: 75
B18: 夏季 | C18: 空气调节室外计算干球温度 | D18: Dry bulb temperature for AC in summer | E18: DB | F18: ℃ | G18: =L18 -> 34.6 | L18: 34.6
B19: 夏季 | C19: 空气调节室外计算湿球温度 | D19: Wet bulb temperature for AC in summer | E19: WB | F19: ℃ | G19: =L19 -> 28.1 | L19: 28.1
B20: 夏季 | C20: 通风室外计算温度 | D20: EFtilated bulb temperature in summer | E20: VB | F20: ℃ | G20: =L20 -> 31.3 | L20: 31.3
B21: 夏季 | C21: 通风室外计算相对湿度 | D21: Relative humidity for EF in summer | E21: RH | F21: ℃ | G21: =L21 -> 68 | L21: 68
B22: 夏季 | C22: 空调室外计算日平均温度 | D22: Average temperatures for AC in summer | E22: Ts | F22: ℃ | G22: =L22 -> 31.5 | L22: 31.5
A23: 风向、 风速及 频率 | B23: 夏季 | C23: 室外平均风速 | D23: Outdoor mean wind speed in summer | E23: v | F23: m/s | G23: =L23 -> 2.8 | L23: 2.8
B24: 夏季 | C24: 室外最多风向 | D24: Wind direction in summer | E24: f | F24: — | G24: =L24 -> SE | L24: SE
B25: 夏季 | C25: 室外最多风向频率 | D25: Wind direction frequencly in summer | E25: f | F25: % | G25: =L25 -> 17 | L25: 17
B26: 夏季 | C26: 室外最多风向平均风速 | D26: Wind direction frequencly wind speed | E26: v | F26: m/s | G26: =L26 -> 3.1 | L26: 3.1
B27: 冬季 | C27: 室外平均风速 | D27: Outdoor mean wind speed in winter | E27: v | F27: m/s | G27: =L27 -> 2.4 | L27: 2.4
B28: 冬季 | C28: 室外最多风向 | D28: Wind direction in winter | E28: f | F28: — | G28: =L28 -> C NE | L28: C NE
B29: 冬季 | C29: 室外最多风向频率 | D29: Wind direction frequencn in winter | E29: f | F29: % | G29: =L29 -> 9 | L29: 9
B30: 冬季 | C30: 室外最多风向平均风速 | D30: Wind direction frequencly wind speed | E30: v | F30: m/s | G30: =L30 -> 3 | I30: WS | L30: 3
B31: 全年 | C31: 年最多风向 | D31: Wind direction in year | E31: v | F31: — | G31: =L31 -> SE | L31: SE
B32: 全年 | C32: 年最多风向频率 | D32: Wind direction frequencnin year | E32: v | F32: — | G32: =L32 -> 13 | L32: 13
A33: 日照冻土 | B33: 冬季 | C33: 日照百分率 | E33: φ | F33: % | G33: =L33 -> 42 | L33: 42
B34: 冬季 | C34: 最大冻土深度 | E34: h | F34: m | G34: =L34 -> 12 | L34: 12
A35: 大气压力 | B35: 夏季 | C35: 室外大气压力 | D35: Barometric pressure in summer | E35: Ps | F35: hPa | G35: =L35 -> 1026.1 | I35: kpa | L35: 1026.1
B36: 冬季 | C36: 室外大气压力 | D36: Barometric pressure in winter | E36: Pw | F36: hPa | G36: =L36 -> 1005.3 | I36: kpa | L36: 1005.3
A37: 设计计算用供暖期天数及其平均温度 | B37: 冬季 | C37: 日平均温度≤+5℃的天数 | E37: d | F37: d | G37: =L37 -> 56 | L37: 56
B38: 冬季 | C38: 日平均温度≤+5℃的起止日期 | E38: date | F38: — | G38: =L38 -> 12.19--02.12 | L38: 12.19--02.12
B39: 冬季 | C39: 平均温度≤+5℃期间内的平均温度 | E39: Tc | F39: ℃ | G39: =L39 -> 3.6 | L39: 3.6
B40: 冬季 | C40: 日平均温度≤+8℃的天数 | E40: d | F40: d | G40: =L40 -> 102 | L40: 102
B41: 冬季 | C41: 日平均温度≤+8℃的起止日期 | E41: date | F41: — | G41: =L41 -> 11.27--03.08 | L41: 11.27--03.08
...

Sheet 2-室内房间参数
A1: 使用说明：仅需根据项目情况输入黄色区域的参数
A2: 序号
A3: 3 | B3: 房间编号 | D3: 2F-01 | E3: 2F-02 | T3: 合计 | X3: 合计 | Z3: 常用室内设计参数
A4: 4 | B4: 房间名 | D4: 1 | E4: 1 | Z4: 温度℃ | AA4: 相对湿度% | AB4: 含湿量g/kg | AC4: 焓值 | AD4: 室内露点温度
A5: 5 | B5: 面积 | C5: m2 | D5: 288 | E5: 288 | T5: =SUM(D5:S5) -> 576 | Z5: 22 | AA5: 0.55 | AB5: 9.1 | AC5: 45.4 | AD5: 12.4
A6: 6 | B6: 吊顶高 | C6: m | D6: 3 | E6: 3 | Z6: 22 | AA6: 0.5 | AB6: 8.3 | AC6: 43.3 | AD6: 11
A7: 7 | B7: 设计温度 | C7: ℃ | D7: 23±2 | E7: 23±2 | Z7: 22 | AA7: 0.45 | AB7: 7.5 | AC7: 41.1 | AD7: 9.4
A8: 8 | B8: 设计湿度 | C8: % | D8: 45±5 | E8: 45±5 | Z8: 23 | AA8: 0.45 | AB8: 8 | AC8: 43.6 | AD8: 10.3
A9: 9 | B9: 净化级别 | C9: CR | D9: ISO5.0 | E9: ISO5.0 | Z9: 24 | AA9: 0.55 | AB9: 10.3 | AC9: 50.5 | AD9: 14.2
A10: 10 | B10: 控制粒径 | C10: um | D10: 0.5 | E10: 0.5 | Z10: 24 | AA10: 0.5 | AB10: 9.4 | AC10: 48.1 | AD10: 12.8
A11: 11 | B11: 压力 | C11: Pa | D11: 20 | E11: 20 | Z11: 24 | AA11: 0.45 | AB11: 8.4 | AC11: 45.7 | AD11: 11.2
A12: 12 | B12: 噪声 | C12: dB(A)
A13: 13 | B13: 特殊要求 | C13: URS
B14: 室内设计参数（夏季）
A15: 15 | B15: 夏季计算温度 | C15: ℃ | D15: =LEFT(D7,2) -> 23 | E15: =LEFT(E7,2) -> 23 | F15: =LEFT(F7,2)
A16: 16 | B16: 夏季温度精度 | C16: ℃ | D16: =RIGHT(D7,1) -> 2 | E16: =RIGHT(E7,1) -> 2
A17: 17 | B17: 夏季计算湿度 | C17: % | D17: =LEFT(D8,2) -> 45 | E17: =LEFT(E8,2) -> 45
A18: 18 | B18: 夏季湿度精度 | C18: % | D18: =RIGHT(D8,2) -> ±5 | E18: =RIGHT(E8,2) -> ±5
A19: 19 | B19: 夏季室内含湿量 | C19: g/kg | D19: 8 | E19: 8
A20: 20 | B20: 夏季室内焓值 | C20: kj/kg | D20: =1.01*D15+(2500+1.84*D15)*(D19/1000) -> 43.56856 | E20: =1.01*E15+(2500+1.84*E15)*(E19/1000) -> 43.56856
A21: 21 | B21: 夏季室内露点温度 | C21: ℃ | D21: 10.3 | E21: 10.3
B22: 室内设计参数（冬季）
A23: 22 | B23: 冬季计算温度 | C23: ℃ | D23: =D15 -> 23 | E23: =E15 -> 23
A24: 23 | B24: 冬季温度精度 | C24: ℃ | D24: =D16 -> 2 | E24: =E16 -> 2
A25: 24 | B25: 冬季计算湿度 | C25: % | D25: =D17 -> 45 | E25: =E17 -> 45
A26: 25 | B26: 冬季湿度精度 | C26: % | D26: =D18 -> ±5 | E26: =E18 -> ±5
A27: 26 | B27: 室内含湿量 | C27: g/kg | D27: =D19 -> 8 | E27: =E19 -> 8
A28: 27 | B28: 室内焓值 | C28: kj/kg | D28: =1.01*D23+(2500+1.84*D23)*(D27/1000) -> 43.56856 | E28: =1.01*E23+(2500+1.84*E23)*(E27/1000) -> 43.56856
A29: 28 | B29: 室内露点温度 | C29: ℃ | D29: =D21 -> 10.3 | E29: =E21 -> 10.3

Sheet 3-洁净区(参数展示）
A1: 使用说明：仅需根据项目情况输入黄色区域的参数
A2: 序号 | B2: 房间编号 | D2: ='2-室内房间参数'!D3 -> 2F-01 | E2: ='2-室内房间参数'!E3 -> 2F-02 | F2: ='2-室内房间参数'!F3 -> 0 | G2: ='2-室内房间参数'!G3 -> 0 | H2: ='2-室内房间参数'!H3 -> 0
A3: 2 | B3: 房间名 | C3: 单位 | D3: ='2-室内房间参数'!D4 -> 1 | E3: ='2-室内房间参数'!E4 -> 1 | F3: ='2-室内房间参数'!F4 -> 0 | G3: ='2-室内房间参数'!G4 -> 0 | H3: ='2-室内房间参数'!H4 -> 0 | L3: 合计 | N3: 备注说明
B4: 面积 | C4: sm | D4: ='2-室内房间参数'!D5 -> 288 | E4: ='2-室内房间参数'!E5 -> 288 | F4: ='2-室内房间参数'!F5 -> 0 | G4: ='2-室内房间参数'!G5 -> 0 | H4: ='2-室内房间参数'!H5 -> 0 | L4: =SUM(D4:E4) -> 576
B5: 吊顶高 | C5: m | D5: ='2-室内房间参数'!D6 -> 3 | E5: ='2-室内房间参数'!E6 -> 3 | F5: ='2-室内房间参数'!F6 -> 0 | G5: ='2-室内房间参数'!G6 -> 0 | H5: ='2-室内房间参数'!H6 -> 0
B6: 设计温度 | C6: °C | D6: ='2-室内房间参数'!D15 -> 23 | E6: ='2-室内房间参数'!E15 -> 23 | F6: ='2-室内房间参数'!F15 | G6: ='2-室内房间参数'!G15 -> 0 | H6: ='2-室内房间参数'!H15 -> 0
B7: 设计湿度 | C7: % | D7: ='2-室内房间参数'!D17 -> 45 | E7: ='2-室内房间参数'!E17 -> 45 | F7: ='2-室内房间参数'!F17 -> 0 | G7: ='2-室内房间参数'!G17 -> 0 | H7: ='2-室内房间参数'!H17 -> 0
B8: 净化级别 | C8: CR | D8: ='2-室内房间参数'!D9 -> ISO5.0 | E8: ='2-室内房间参数'!E9 -> ISO5.0 | F8: ='2-室内房间参数'!F9 -> 0 | G8: ='2-室内房间参数'!G9 -> 0 | H8: ='2-室内房间参数'!H9 -> 0
B9: 控制粒径 | C9: um | D9: ='2-室内房间参数'!D10 -> 0.5 | E9: ='2-室内房间参数'!E10 -> 0.5 | F9: ='2-室内房间参数'!F10 -> 0 | G9: ='2-室内房间参数'!G10 -> 0 | H9: ='2-室内房间参数'!H10 -> 0
B10: 压力 | C10: Pa | D10: ='2-室内房间参数'!D11 -> 20 | E10: ='2-室内房间参数'!E11 -> 20 | F10: ='2-室内房间参数'!F11 -> 0 | G10: ='2-室内房间参数'!G11 -> 0 | H10: ='2-室内房间参数'!H11 -> 0
B11: 室内空气含湿量 | C11: g/kg | D11: ='2-室内房间参数'!D19 -> 8 | E11: ='2-室内房间参数'!E19 -> 8 | F11: ='2-室内房间参数'!F19 -> 0 | G11: ='2-室内房间参数'!G19 -> 0 | H11: ='2-室内房间参数'!H19 -> 0 | L11: =D11 -> 8
B12: 室内空气焓值 | C12: kj/kg | D12: ='2-室内房间参数'!D20 -> 43.56856 | E12: ='2-室内房间参数'!E20 -> 43.56856 | F12: ='2-室内房间参数'!F20 -> 0 | G12: ='2-室内房间参数'!G20 -> 0 | H12: ='2-室内房间参数'!H20 -> 0 | L12: =D12 -> 43.56856
B13: 室内空气露点温度 | C13: °C | D13: ='2-室内房间参数'!D21 -> 10.3 | E13: ='2-室内房间参数'!E21 -> 10.3 | F13: ='2-室内房间参数'!F21 -> 0 | G13: ='2-室内房间参数'!G21 -> 0 | H13: ='2-室内房间参数'!H21 -> 0 | L13: =D13 -> 10.3
B14: 洁净换气次数 | C14: ACH | N14: 按净化级别，详见表格
B15: 洁净截面风速 | C15: m/s | N15: 按净化级别，详见表格
B16: 洁净循环风量 | C16: CMH | D16: =MAX(D15*D4*3600,D4*D5*D14) -> 0 | E16: =MAX(E15*E4*3600,E4*E5*E14) -> 0 | F16: =MAX(F15*F4*3600,F4*F5*F14) -> 0 | G16: =MAX(G15*G4*3600,G4*G5*G14) -> 0 | H16: =MAX(H15*H4*3600,H4*H5*H14) -> 0 | L16: =SUM(D16:E16) -> 0
B17: FFU满布率 | C17: % | D17: =D16/3600/(D4*D74) -> 0 | E17: =E16/3600/(E4*E74) -> 0 | F17: =F16/3600/(F4*F74) -> #DIV/0! | G17: =G16/3600/(G4*G74) -> #DIV/0! | H17: =H16/3600/(H4*H74) -> #DIV/0!
B18: 人员数量 | C18: 人
B19: 工艺热排风量-GEX | C19: CMH | L19: =SUM(D19:E19) -> 0
B20: 工艺酸排风量-SEX | C20: CMH | L20: =SUM(D20:E20) -> 0
B21: 工艺碱排风量-AEX | C21: CMH | L21: =SUM(D21:E21) -> 0
B22: 工艺有机排风量-VEX | C22: CMH | L22: =SUM(D22:E22) -> 0
B23: 一般全室排风-CEX | C23: CMH | L23: =SUM(D23:E23) -> 0
B24: 室内正压风量（按经验公式） | C24: CMH | D24: =D4*D5*1.2*(D10/10)^0.5 -> 1466.2566 | E24: =E4*E5*1.2*(E10/10)^0.5 -> 1466.2566 | F24: =F4*F5*1.2*(F10/10)^0.5 -> 0 | G24: =G4*G5*1.2*(G10/10)^0.5 -> 0 | H24: =H4*H5*1.2*(H10/10)^0.5 -> 0 | L24: =SUM(D24:E24) -> 2932.5132
B25: 正压风量换气次数
B26: 室内正压风量（按换气次数） | C26: CMH | D26: =D25*D4*D5 -> 0 | E26: =E25*E4*E5 -> 0 | F26: =F25*F4*F5 -> 0 | G26: =G25*G4*G5 -> 0 | H26: =H25*H4*H5 -> 0
B27: 室内正压风量(取大值） | C27: CMH | D27: =MAX(D24,D26) -> 1466.2566 | E27: =MAX(E24,E26) -> 1466.2566 | F27: =MAX(F24,F26) -> 0 | G27: =MAX(G24,G26) -> 0 | H27: =MAX(H24,H26) -> 0
B28: 人员新风量指标 | C28: CMH/人 | D28: 40 | E28: 40 | F28: 40 | G28: 40 | H28: 40
B29: 人员新风量 | C29: CMH | D29: =D18*D28 -> 0 | E29: =E18*E28 -> 0 | F29: =F18*F28 -> 0 | G29: =G18*G28 -> 0 | H29: =H18*H28 -> 0 | L29: =SUM(D29:E29) -> 0
B30: 人员湿负荷指标 | C30: g/h/人 | D30: 80 | E30: 80 | F30: 80 | G30: 80 | H30: 80
B31: 人员湿负荷 | C31: g/h | D31: =D18*D30 -> 0 | E31: =E18*E30 -> 0 | F31: =F18*F30 -> 0 | G31: =G18*G30 -> 0 | H31: =H18*H30 -> 0 | L31: =SUM(D31:E31) -> 0
B32: 室内冷负荷计算
B33: 夏冬季
B34: 维护结构冷负荷指标 | C34: w/m2 | D34: 50 | E34: 50 | F34: 50 | G34: 50 | H34: 50
B35: 维护结构冷负荷 | C35: Kw | D35: =D4*D34/1000 -> 14.4 | E35: =E4*E34/1000 -> 14.4 | F35: =F4*F34/1000 -> 0 | G35: =G4*G34/1000 -> 0 | H35: =H4*H34/1000 -> 0 | L35: =SUM(D35:E35) -> 28.8
B36: 维护结构热负荷指标 | C36: w/m2 | D36: 40 | E36: 40 | F36: 40 | G36: 40 | H36: 40
B37: 维护结构热负荷 | C37: Kw | D37: =D4*D36/1000 -> 11.52 | E37: =E4*E36/1000 -> 11.52 | F37: =F4*F36/1000 -> 0 | G37: =G4*G36/1000 -> 0 | H37: =H4*H36/1000 -> 0 | L37: =SUM(D37:E37) -> 23.04
B38: 人员冷负荷指标 | C38: w/人 | D38: 118 | E38: 118 | F38: 118 | G38: 118 | H38: 118
B39: 人员冷负荷(显热) | C39: Kw | D39: =D18*D38/1000 -> 0 | E39: =E18*E38/1000 -> 0 | F39: =F18*F38/1000 -> 0 | G39: =G18*G38/1000 -> 0 | H39: =H18*H38/1000 -> 0 | L39: =SUM(D39:E39) -> 0
B40: 灯光冷负荷 | C40: Kw | D40: =D4*0.02 -> 5.76 | E40: =E4*0.02 -> 5.76 | F40: =F4*0.02 -> 0 | G40: =G4*0.02 -> 0 | H40: =H4*0.02 -> 0 | L40: =SUM(D40:E40) -> 11.52
...
